Workbook

Sheet Project Overview
B2: S.N | C2: Project Overview | D2: Description
B3: 1 | C3: Project Title | D3: Budget Tracker (Excel Dashboard)
C4: Description | D4: Tracks monthly income, expenses, and savings with automated summaries and charts.
C5: Key Excel Features Used | D5: SUM, MAX, MIN, cell references
D6: Pie charts for data visualization
D7: Sheet referencing .
C8: Insights Generated | D8: Total annual savings
D9: Highest and lowest expense months
D10: Expense vs. Income ratio
B12: 2 | C12: Project Description | D12: Built in Excel using real-world income and expense data.
D13: Includes monthly summaries, annual KPIs, and pie charts for spending visualization.
D14: Automates savings calculations using formulas and cross-sheet references.
D15: Displays annual total income, expenses, and net savings in a professional dashboard layout.

Sheet Dashboard
B2: Budget Tracker
L3: Annual Income | P3: Annual Expense | T3: Annual Saving
L5: =SUM(B10,J10,R10,B35,J35,R35,B60,J60,R60,Z10,Z35,Z60) -> 656691 | P5: =SUM(K10,S10,C35,K35,S35,C60,K60,S60,Z10,Z35,Z60) -> 574118 | T5: =L5-P5 -> 82573
B7: Jan Summary | J7: Feb Summary | R7: Mar Summary | Z7: Apr Summary
B8: Income | C8: Expense | D8: Max | F8: Min | H8: Saving | J8: Income | K8: Expense | L8: Max | N8: Min | P8: Saving | R8: Income | S8: Expense | T8: Max | V8: Min | X8: Saving | Z8: Income | AA8: Expense | AB8: Max | AD8: Min | AF8: Saving
D9: Income | E9: Expense | F9: Income | G9: Expense | L9: Income | M9: Expense | N9: Income | O9: Expense | T9: Income | U9: Expense | V9: Income | W9: Expense | AB9: Income | AC9: Expense | AD9: Income | AE9: Expense
B10: =Months!D35 -> 46640 | C10: =Months!E36 -> 44937 | D10: =Months!D37 -> 40000 | E10: =Months!E38 -> 12000 | F10: =Months!D39 -> 50 | G10: =Months!E40 -> 114 | H10: =Months!D41 -> 1703 | J10: =Months!L35 -> 41101 | K10: =Months!M36 -> 39428 | L10: =Months!L37 -> 30000 | M10: =Months!M38 -> 2335 | N10: =Months!L39 -> 50 | O10: =Months!M40 -> 41 | P10: =Months!L41 -> 1673 | R10: =Months!T35 -> 34500 | S10: =Months!U36 -> 71300 | T10: =Months!T37 -> 31500 | U10: =Months!U38 -> 15000 | V10: =Months!T39 -> 3000 | W10: =Months!U40 -> 150 | X10: =Months!T41 -> -36800 | Z10: =Months!AB35 -> 50670 | AA10: =Months!AC36 -> 48500 | AB10: =Months!AB37 -> 30500 | AC10: =Months!AC38 -> 15000 | AD10: =Months!AB39 -> 600 | AE10: =Months!AC40 -> 100 | AF10: =Months!AB41 -> 2170
B11: Strong start — High income and controlled expenses led to solid savings. | J11: Stable month — Slight drop in income, but expenses remained balanced with modest savings. | R11: Overspent — Expenses exceeded income, resulting in a negative saving. | Z11: Slight loss — Expenses slightly exceeded income, resulting in a small negative saving.
B32: May Summary | J32: Jun Summary | R32: Jul Summary | Z32: Aug Summary
B33: Income | C33: Expense | D33: Max | F33: Min | H33: Saving | J33: Income | K33: Expense | L33: Max | N33: Min | P33: Saving | R33: Income | S33: Expense | T33: Max | V33: Min | X33: Saving | Z33: Income | AA33: Expense | AB33: Max | AD33: Min | AF33: Saving
D34: Income | E34: Expense | F34: Income | G34: Expense | L34: Income | M34: Expense | N34: Income | O34: Expense | T34: Income | U34: Expense | V34: Income | W34: Expense | AB34: Income | AC34: Expense | AD34: Income | AE34: Expense
B35: =Months!AJ35 -> 53020 | C35: =Months!AK36 -> 52100 | D35: =Months!AJ37 -> 53020 | E35: =Months!AK38 -> 52100 | F35: =Months!AJ39 -> 7020 | G35: =Months!AK40 -> 100 | H35: =Months!AJ41 -> 920 | J35: =Months!AR35 -> 36000 | K35: =Months!AS36 -> 39400 | L35: =Months!AR37 -> 30000 | M35: =Months!AS38 -> 15000 | N35: =Months!AR39 -> 6000 | O35: =Months!AS40 -> 100 | P35: =Months!AR41 -> -3400 | R35: =Months!AZ35 -> 123550 | S35: =Months!BA36 -> 54100 | T35: =Months!AZ37 -> 80050 | U35: =Months!BA38 -> 15000 | V35: =Months!AZ39 -> 3000 | W35: =Months!BA40 -> 150 | X35: =Months!AZ41 -> 69450 | Z35: =Months!BH35 -> 30500 | AA35: =Months!BI36 -> 72200 | AB35: =Months!BH37 -> 30500 | AC35: =Months!BI38 -> 15000 | AD35: =Months!BH39 -> 30500 | AE35: =Months!BI40 -> 400 | AF35: =Months!BH41 -> -41700
B36: Barely positive — Income and expense were nearly equal, resulting in minimal savings. | J36: Overspent — Expenses exceeded income, leading to a small loss. | R36: Excellent month — High income and low expenses resulted in strong savings. | Z36: Overspending alert — Expenses far exceeded income, leading to a significant loss.
B57: Sep Summary | J57: Oct Summary | R57: Nov Summary | Z57: Dec Summary
B58: Income | C58: Expense | D58: Max | F58: Min | H58: Saving | J58: Income | K58: Expense | L58: Max | N58: Min | P58: Saving | R58: Income | S58: Expense | T58: Max | V58: Min | X58: Saving | Z58: Income | AA58: Expense | AB58: Max | AD58: Min | AF58: Saving
D59: Income | E59: Expense | F59: Income | G59: Expense | L59: Income | M59: Expense | N59: Income | O59: Expense | T59: Income | U59: Expense | V59: Income | W59: Expense | AB59: Income | AC59: Expense | AD59: Income | AE59: Expense
B60: =Months!BP35 -> 67980 | C60: =Months!BQ36 -> 67980 | D60: =Months!BP37 -> 31000 | E60: =Months!BQ38 -> 15000 | F60: =Months!BP39 -> 900 | G60: =Months!BQ40 -> 100 | H60: =Months!BP41 -> 0 | J60: =Months!BX35 -> 57530 | K60: =Months!BY36 -> 40190 | L60: =Months!BX37 -> 28000 | M60: =Months!BY38 -> 5000 | N60: =Months!BX39 -> 3000 | O60: =Months!BY40 -> 150 | P60: =Months!BX41 -> 17340 | R60: =Months!CF35 -> 42000 | S60: =Months!CG36 -> 55250 | T60: =Months!CF37 -> 31500 | U60: =Months!CG38 -> 15000 | V60: =Months!CF39 -> 5000 | W60: =Months!CG40 -> 100 | X60: =Months!CF41 -> -13250 | Z60: =Months!CN35 -> 73200 | AA60: =Months!CO36 -> 67450 | AB60: =Months!CN37 -> 32000 | AC60: =Months!CO38 -> 8000 | AD60: =Months!CN39 -> 1200 | AE60: =Months!CO40 -> 500 | AF60: =Months!CN41 -> 5750
B61: Balanced month — Income and expenses were nearly equal, resulting in a small saving. | J61: Repeat pattern — Same income and expense as September, with identical savings. | R61: Loss recorded — Expenses exceeded income significantly, leading to a notable deficit. | Z61: Positive close — Strong income and controlled expenses led to healthy savings.

Sheet Months
A1: January | I1: February | Q1: March | Y1: April | AG1: May | AO1: June | AW1: July | BE1: August | BM1: September | BU1: October | CC1: November | CK1: December
A2: Date | B2: Category | C2: Description | D2: Income | E2: Expense | I2: Date | J2: Category | K2: Description | L2: Income | M2: Expense | Q2: Date | R2: Category | S2: Description | T2: Income | U2: Expense | Y2: Date | Z2: Category | AA2: Description | AB2: Income | AC2: Expense | AG2: Date | AH2: Category | AI2: Description | AJ2: Income | AK2: Expense | AO2: Date | AP2: Category | AQ2: Description | AR2: Income | AS2: Expense | AW2: Date | AX2: Category | AY2: Description | AZ2: Income | BA2: Expense | BE2: Date | BF2: Category | BG2: Description | BH2: Income | BI2: Expense | BM2: Date | BN2: Category | BO2: Description | BP2: Income | BQ2: Expense | BU2: Date | BV2: Category | BW2: Description | BX2: Income | BY2: Expense | CC2: Date | CD2: Category | CE2: Description | CF2: Income | CG2: Expense | CK2: Date | CL2: Category | CM2: Description | CN2: Income | CO2: Expense
A3: 2025-01-01 | B3: Shopping | C3: Electricity Bill | E3: 2028 | I3: 2025-02-01 | J3: Entertainment | K3: February Salary | L3: 3200 | M3: 387 | Q3: 45717 | R3: Education | S3: Course Fee | U3: 5000 | Y3: 45748 | Z3: Food | AA3: Groceries | AC3: 1900 | AG3: 45778 | AH3: Entertainment | AI3: Theme Park | AK3: 3500 | AO3: 45809 | AP3: Food | AQ3: Groceries | AS3: 1500 | AW3: 45839 | AX3: Food | AY3: Groceries | BA3: 1900 | BE3: 45870 | BF3: Transport | BG3: Flight Ticket (Vacation) | BI3: 12000 | BM3: 45901 | BN3: Education | BO3: Tuition Fee | BP3: 900 | BQ3: 5000 | BU3: 45931 | BV3: Food | BW3: Groceries | BY3: 1600 | CC3: 45962 | CD3: Food | CE3: Groceries | CG3: 1950 | CK3: 45992 | CL3: Shopping | CM3: Holiday Gifts | CO3: 8000
A4: 2025-01-02 | B4: Entertainment | C4: Bus Fare | E4: 669 | I4: 2025-02-02 | J4: Entertainment | K4: Groceries | M4: 1290 | Q4: 45718 | R4: Food | S4: Groceries | U4: 1450 | Y4: 45749 | Z4: Utilities | AA4: Rent | AC4: 15000 | AG4: 45779 | AH4: Utilities | AI4: Rent | AK4: 15000 | AO4: 45810 | AP4: Utilities | AQ4: Rent | AS4: 15000 | AW4: 45840 | AX4: Utilities | AY4: Rent | BA4: 15000 | BE4: 45871 | BF4: Utilities | BG4: Rent | BI4: 15000 | BM4: 45902 | BN4: Utilities | BO4: Rent | BQ4: 15000 | BU4: 45932 | BV4: Utilities | BW4: Rent | BX4: 26530 | BY4: 5000 | CC4: 45963 | CD4: Utilities | CE4: Rent | CG4: 15000 | CK4: 45993 | CL4: Utilities | CM4: Rent | CN4: 23000 | CO4: 500
A5: 2025-01-03 | B5: Utilities | C5: Doctor Visit | E5: 1610 | I5: 2025-02-03 | J5: Utilities | K5: Electricity Bill | M5: 147 | Q5: 45719 | R5: Utilities | S5: Rent | U5: 15000 | Y5: 45750 | Z5: Education | AA5: Books | AC5: 750 | AG5: 45780 | AH5: Food | AI5: Groceries | AK5: 1800 | AO5: 45811 | AP5: Transport | AQ5: Bus Fare | AS5: 100 | AW5: 45841 | AX5: Health | AY5: Gym Fee | BA5: 1800 | BE5: 45872 | BF5: Food | BG5: Groceries | BI5: 1700 | BM5: 45903 | BN5: Food | BO5: Groceries | BQ5: 1850 | BU5: 45933 | BV5: Health | BW5: Vitamins | BY5: 900 | CC5: 45964 | CD5: Shopping | CE5: Gift | CG5: 2000 | CK5: 45994 | CL5: Food | CM5: Groceries | CO5: 2800
A6: 2025-01-04 | B6: Shopping | C6: Movie | E6: 1383 | I6: 2025-02-04 | J6: Utilities | K6: Electricity Bill | M6: 2200 | Q6: 45720 | R6: Transport | S6: Bus Fare | U6: 150 | Y6: 45751 | Z6: Transport | AA6: Bus Pass | AC6: 1200 | AG6: 45781 | AH6: Shopping | AI6: Plants | AK6: 1200 | AO6: 45812 | AP6: Education | AQ6: Online Test | AS6: 500 | AW6: 45842 | AX6: Transport | AY6: Fuel | BA6: 2200 | BE6: 45873 | BF6: Shopping | BG6: Luggage | BI6: 4000 | BM6: 45904 | BN6: Transport | BO6: Bus Pass | BQ6: 1200 | BU6: 45934 | BV6: Transport | BW6: Bus Fare | BY6: 150 | CC6: 45965 | CD6: Transport | CE6: Bus Fare | CG6: 150 | CK6: 45995 | CL6: Transport | CM6: Bus Pass | CO6: 1200
A7: 2025-01-05 | B7: Entertainment | C7: Groceries | E7: 1356 | I7: 2025-02-05 | J7: Shopping | K7: Groceries | M7: 1468 | Q7: 45721 | R7: Shopping | S7: Clothes | U7: 3500 | Y7: 45752 | Z7: Shopping | AA7: Gift | AC7: 2500 | AG7: 45782 | AH7: Transport | AI7: Fuel | AK7: 2000 | AO7: 45813 | AP7: Health | AQ7: Pharmacy | AS7: 400 | AW7: 45843 | AX7: Shopping | AY7: Clothes | BA7: 3100 | BE7: 45874 | BF7: Transport | BG7: Local Travel | BI7: 800 | BM7: 45905 | BN7: Shopping | BO7: Gadget | BP7: 5000 | BQ7: 1000 | BU7: 45935 | BV7: Shopping | BW7: Small Gift | BY7: 1000 | CC7: 45966 | CD7: Education | CE7: Course Fee | CF7: 5000 | CG7: 100 | CK7: 45996 | CL7: Entertainment | CM7: Holiday Party Prep | CO7: 4500
A8: 2025-01-06 | B8: Utilities | C8: Books | E8: 721 | I8: 2025-02-06 | J8: Utilities | K8: February Salary | L8: 30000 | M8: 1510 | Q8: 45722 | R8: Entertainment | S8: Movie | U8: 850 | Y8: 45753 | Z8: Entertainment | AA8: Streaming Sub. | AC8: 500 | AG8: 45783 | AH8: Health | AI8: Gym Fee | AK8: 1800 | AO8: 45814 | AP8: Food | AQ8: Takeout | AS8: 800 | AW8: 45844 | AX8: Entertainment | AY8: Social Event | AZ8: 5000 | BA8: 200 | BE8: 45875 | BF8: Entertainment | BG8: Museum Entry | BI8: 1000 | BM8: 45906 | BN8: Entertainment | BO8: Social Event | BQ8: 8000 | BU8: 45936 | BV8: Entertainment | BW8: Movie | BY8: 700 | CC8: 45967 | CD8: Health | CE8: Gym Fee | CG8: 1800 | CK8: 45997 | CL8: Health | CM8: Doctor Visit | CN8: 1200
A9: 2025-01-07 | B9: Health | C9: January Salary | D9: 40000 | E9: 147 | I9: 2025-02-07 | J9: Education | K9: Doctor Visit | M9: 230 | Q9: 45723 | R9: Health | S9: Doctor Visit | T9: 3000 | U9: 600 | Y9: 45754 | Z9: Food | AA9: Restaurant | AC9: 1850 | AG9: 45784 | AH9: Education | AI9: Software | AK9: 2500 | AO9: 45815 | AP9: Shopping | AQ9: Stationery | AS9: 300 | AW9: 45845 | AX9: Food | AY9: Restaurant | BA9: 2300 | BE9: 45876 | BF9: Food | BG9: Restaurant (Vacation) | BI9: 3500 | BM9: 45907 | BN9: Health | BO9: Gym Fee | BQ9: 3000 | BU9: 45937 | BV9: Food | BW9: Takeout | BY9: 800 | CC9: 45968 | CD9: Food | CE9: Takeout | CG9: 850 | CK9: 45998 | CL9: Food | CM9: Restaurant | CO9: 3500
A10: 2025-01-08 | B10: Entertainment | C10: Doctor Visit | E10: 2260 | I10: 2025-02-08 | J10: Transport | K10: Doctor Visit | M10: 1128 | Q10: 45724 | R10: Food | S10: Groceries | U10: 2100 | Y10: 45755 | Z10: Health | AA10: Doctor Visit | AC10: 800 | AG10: 45785 | AH10: Food | AI10: Dinner Out | AK10: 1600 | AO10: 45816 | AP10: Utilities | AQ10: Water Bill | AS10: 650 | AW10: 45846 | AX10: Education | AY10: Books | BA10: 850 | BE10: 45877 | BF10: Health | BG10: Travel Insurance | BI10: 1500 | BM10: 45908 | BN10: Food | BO10: Restaurant | BQ10: 2200 | BU10: 45938 | BV10: Education | BW10: Online Course | BY10: 1500 | CC10: 45969 | CD10: Entertainment | CE10: Movie | CG10: 750 | CK10: 45999 | CL10: Education | CM10: Books | CO10: 800
A11: 2025-01-09 | B11: Transport | C11: Books | E11: 1391 | I11: 2025-02-09 | J11: Entertainment | K11: Doctor Visit | M11: 1593 | Q11: 45725 | R11: Utilities | S11: Electricity Bill | U11: 1800 | Y11: 45756 | Z11: Utilities | AA11: Electricity Bill | AC11: 1500 | AG11: 45786 | AH11: Utilities | AI11: Water Bill | AK11: 700 | AO11: 45817 | AP11: Entertainment | AQ11: Movie | AS11: 700 | AW11: 45847 | AX11: Utilities | AY11: Electricity Bill | BA11: 1400 | BE11: 45878 | BF11: Shopping | BG11: Souvenirs | BI11: 2500 | BM11: 45909 | BN11: Utilities | BO11: Water Bill | BQ11: 700 | BU11: 45939 | BV11: Utilities | BW11: Electricity Bill | BY11: 4590 | CC11: 45970 | CD11: Utilities | CE11: Electricity Bill | CG11: 1450 | CK11: 46000 | CL11: Utilities | CM11: Electricity Bill | CO11: 1500
A12: 2025-01-10 | B12: Health | C12: January Salary | D12: 3690 | E12: 656 | I12: 2025-02-10 | J12: Salary | K12: Clothes | M12: 2132 | Q12: 45726 | R12: Education | S12: Books | U12: 950 | Y12: 45757 | Z12: Food | AA12: Groceries | AC12: 2200 | AG12: 45787 | AH12: Shopping | AI12: Gadget Accessory | AK12: 900 | AO12: 45818 | AP12: Food | AQ12: Groceries | AS12: 2000 | AW12: 45848 | AX12: Food | AY12: Groceries | BA12: 2500 | BE12: 45879 | BF12: Transport | BG12: Intercity Train | BI12: 1800 | BM12: 45910 | BN12: Education | BO12: Books | BP12: 1600 | BQ12: 400 | BU12: 45940 | BV12: Food | BW12: Groceries | BY12: 2100 | CC12: 45971 | CD12: Food | CE12: Groceries | CG12: 2300 | CK12: 46001 | CL12: Shopping | CM12: Festive Decor | CO12: 3000
A13: 2025-01-11 | B13: Food | C13: Clothes | E13: 706 | I13: 2025-02-11 | J13: Food | K13: Groceries | M13: 2135 | Q13: 45727 | R13: Shopping | S13: Electronics | U13: 7000 | Y13: 45758 | Z13: Education | AA13: Online Course | AC13: 1500 | AG13: 45788 | AH13: Entertainment | AI13: Streaming Sub. | AK13: 500 | AO13: 45819 | AP13: Transport | AQ13: Fuel | AS13: 1500 | AW13: 45849 | AX13: Shopping | AY13: Accessories | BA13: 1100 | BE13: 45880 | BF13: Entertainment | BG13: Activity Fee | BI13: 2000 | BM13: 45911 | BN13: Shopping | BO13: Gift | BQ13: 2500 | BU13: 45941 | BV13: Transport | BW13: Cab | BY13: 400 | CC13: 45972 | CD13: Shopping | CE13: Clothes | CG13: 3200 | CK13: 46002 | CL13: Food | CM13: Groceries | CO13: 3200
A14: 2025-01-13 | B14: Health | C14: Books | E14: 1109 | I14: 2025-02-12 | J14: Shopping | K14: February Salary | L14: 50 | M14: 2163 | Q14: 45728 | R14: Food | S14: Restaurant | U14: 1750 | Y14: 45759 | Z14: Shopping | AA14: Cosmetics | AC14: 1100 | AG14: 45789 | AH14: Food | AI14: Groceries | AK14: 2400 | AO14: 45820 | AP14: Education | AQ14: Books | AS14: 600 | AW14: 45850 | AX14: Transport | AY14: Train Fare | BA14: 700 | BE14: 45881 | BF14: Food | BG14: Groceries | BI14: 2200 | BM14: 45912 | BN14: Transport | BO14: Cab | BQ14: 4580 | BU14: 45942 | BV14: Shopping | BW14: Stationery | BY14: 300 | CC14: 45973 | CD14: Transport | CE14: Fuel | CG14: 2100 | CK14: 46003 | CL14: Transport | CM14: Fuel | CO14: 2500
A15: 2025-01-14 | B15: Food | C15: Electricity Bill | E15: 114 | I15: 2025-02-13 | J15: Education | K15: Bus Fare | M15: 2188 | Q15: 45729 | R15: Transport | S15: Fuel | U15: 2500 | Y15: 45760 | Z15: Transport | AA15: Metro Fare | AC15: 250 | AG15: 45790 | AH15: Transport | AI15: Bus Fare | AK15: 150 | AO15: 45821 | AP15: Health | AQ15: Vitamins | AS15: 900 | AW15: 45851 | AX15: Entertainment | AY15: Movie | BA15: 800 | BE15: 45882 | BF15: Utilities | BG15: Phone Bill | BI15: 700 | BM15: 45913 | BN15: Entertainment | BO15: Movie | BQ15: 950 | BU15: 45943 | BV15: Health | BW15: Pharmacy | BY15: 500 | CC15: 45974 | CD15: Education | CE15: Books | CG15: 900 | CK15: 46004 | CL15: Entertainment | CM15: Tickets | CO15: 2500
A16: 2025-01-15 | B16: Health | C16: Movie | E16: 605 | I16: 2025-02-14 | J16: Shopping | K16: Groceries | M16: 446 | Q16: 45730 | R16: Entertainment | S16: Concert Ticket | U16: 4500 | Y16: 45761 | Z16: Entertainment | AA16: Movie | AC16: 700 | AG16: 45791 | AH16: Salary | AI16: Bonus | AJ16: 15000 | AO16: 45822 | AP16: Entertainment | AQ16: Home Stream | AS16: 200 | AW16: 45852 | AX16: Health | AY16: Pharmacy | BA16: 500 | BE16: 45883 | BF16: Education | BG16: Magazine Sub. | BI16: 400 | BM16: 45914 | BN16: Food | BO16: Groceries | BQ16: 2500 | BU16: 45944 | BV16: Entertainment | BW16: Gaming | BY16: 1200 | CC16: 45975 | CD16: Health | CE16: Doctor Visit | CG16: 1500 | CK16: 46005 | CL16: Health | CM16: Massage | CN16: 5000
A17: 2025-01-16 | B17: Entertainment | C17: Movie | E17: 1462 | I17: 2025-02-15 | J17: Utilities | K17: Movie | M17: 1434 | Q17: 45731 | R17: Salary | S17: March Salary | T17: 31500 | Y17: 45762 | Z17: Salary | AA17: April Salary | AB17: 30500 | AG17: 45792 | AH17: Salary | AI17: May Salary | AJ17: 31000 | AO17: 45823 | AP17: Salary | AQ17: June Salary | AR17: 30000 | AW17: 45853 | AX17: Salary | AY17: July Salary | AZ17: 31000 | BE17: 45884 | BF17: Salary | BG17: August Salary | BH17: 30500 | BM17: 45915 | BN17: Salary | BO17: September Salary | BP17: 31000 | BU17: 45945 | BV17: Salary | BW17: October Salary | BX17: 28000 | CC17: 45976 | CD17: Salary | CE17: November Salary | CF17: 31500 | CK17: 46006 | CL17: Salary | CM17: December Salary | CN17: 32000
A18: 2025-01-17 | B18: Salary | C18: Clothes | E18: 262 | I18: 2025-02-16 | J18: Health | K18: February Salary | L18: 5010 | M18: 1683 | Q18: 45732 | R18: Food | S18: Groceries | U18: 1550 | Y18: 45763 | Z18: Food | AA18: Takeout | AC18: 900 | AG18: 45793 | AH18: Health | AI18: Pharmacy | AK18: 800 | AO18: 45824 | AP18: Food | AQ18: Restaurant | AS18: 1400 | AW18: 45854 | AX18: Food | AY18: Takeout | BA18: 1200 | BE18: 45885 | BF18: Food | BG18: Takeout | BI18: 900 | BM18: 45916 | BN18: Salary | BO18: Performance Bonus | BP18: 10000 | BU18: 45946 | BV18: Food | BW18: Restaurant | BY18: 1800 | CC18: 45977 | CD18: Entertainment | CE18: Social Event | CG18: 1800 | CK18: 46007 | CL18: Food | CM18: Takeout | CO18: 1500
A19: 2025-01-18 | B19: Education | C19: Clothes | E19: 1905 | I19: 2025-02-17 | J19: Transport | K19: Doctor Visit | M19: 1946 | Q19: 45733 | R19: Health | S19: Pharmacy | U19: 600 | Y19: 45764 | Z19: Health | AA19: Vitamins | AB19: 2070 | AC19: 100 | AG19: 45794 | AH19: Food | AI19: Takeout | AK19: 950 | AO19: 45825 | AP19: Shopping | AQ19: Small Purchase | AS19: 500 | AW19: 45855 | AX19: Education | AY19: Online Course | BA19: 1000 | BE19: 45886 | BF19: Shopping | BG19: Clothes | BI19: 2800 | BM19: 45917 | BN19: Health | BO19: Doctor Visit | BQ19: 1500 | BU19: 45947 | BV19: Education | BW19: Books | BY19: 700 | CC19: 45978 | CD19: Food | CE19: Restaurant | CG19: 2000 | CK19: 46008 | CL19: Shopping | CM19: Clothes | CO19: 4200
A20: 2025-01-19 | B20: Salary | C20: Movie | E20: 965 | I20: 2025-02-18 | J20: Education | K20: Books | M20: 1679 | Q20: 45734 | R20: Shopping | S20: Home Decor | U20: 2200 | Y20: 45765 | Z20: Shopping | AA20: Book | AC20: 600 | AG20: 45795 | AH20: Education | AI20: Stationery | AK20: 300 | AO20: 45826 | AP20: Utilities | AQ20: Electricity Bill | AS20: 1200 | AW20: 45856 | AX20: Shopping | AY20: Home Supplies | BA20: 1500 | BE20: 45887 | BF20: Health | BG20: Pharmacy | BI20: 600 | BM20: 45918 | BN20: Utilities | BO20: Electricity Bill | BQ20: 1500 | BU20: 45948 | BV20: Shopping | BW20: Home Needs | BY20: 1400 | CC20: 45979 | CD20: Shopping | CE20: Electronics | CG20: 4000 | CK20: 46009 | CL20: Utilities | CM20: Water Bill | CO20: 750
A21: 2025-01-20 | B21: Entertainment | C21: Bus Fare | E21: 2134 | I21: 2025-02-19 | J21: Utilities | K21: Bus Fare | M21: 1796 | Q21: 45735 | R21: Education | S21: Online Subscription | U21: 500 | Y21: 45766 | Z21: Utilities | AA21: Internet Bill | AC21: 1000 | AG21: 45796 | AH21: Utilities | AI21: Electricity Bill | AK21: 1400 | AO21: 45827 | AP21: Transport | AQ21: Cab | AS21: 350 | AW21: 45857 | AX21: Utilities | AY21: Water Bill | BA21: 750 | BE21: 45888 | BF21: Utilities | BG21: Electricity Bill | BI21: 1600 | BM21: 45919 | BN21: Shopping | BO21: Home Supplies | BQ21: 3500 | BU21: 45949 | BV21: Utilities | BW21: Water Bill | BY21: 650 | CC21: 45980 | CD21: Utilities | CE21: Water Bill | CG21: 700 | CK21: 46010 | CL21: Transport | CM21: Cab | CO21: 600
A22: 2025-01-21 | B22: Health | C22: Books | E22: 949 | I22: 2025-02-20 | J22: Food | K22: Doctor Visit | M22: 1501 | Q22: 45736 | R22: Utilities | S22: Water Bill | U22: 750 | Y22: 45767 | Z22: Food | AA22: Groceries | AC22: 2500 | AG22: 45797 | AH22: Shopping | AI22: Clothes | AJ22: 7020 | AK22: 100 | AO22: 45828 | AP22: Food | AQ22: Groceries | AS22: 2100 | AW22: 45858 | AX22: Transport | AY22: Cab | AZ22: 3000 | BE22: 45889 | BF22: Transport | BG22: Fuel | BI22: 2100 | BM22: 45920 | BN22: Food | BO22: Takeout | BQ22: 1100 | BU22: 45950 | BV22: Transport | BW22: Fuel | BY22: 1800 | CC22: 45981 | CD22: Transport | CE22: Cab | CG22: 500 | CK22: 46011 | CL22: Food | CM22: Party Supplies | CO22: 4000
A23: 2025-01-22 | B23: Transport | C23: Movie | E23: 1282 | I23: 2025-02-21 | J23: Education | K23: Books | M23: 2029 | Q23: 45737 | R23: Food | S23: Delivery | U23: 900 | Y23: 45768 | Z23: Transport | AA23: Cab | AC23: 450 | AG23: 45798 | AH23: Transport | AI23: Cab | AK23: 500 | AO23: 45829 | AP23: Education | AQ23: Magazine Sub. | AS23: 400 | AW23: 45859 | AX23: Food | AY23: Groceries | BA23: 2800 | BE23: 45890 | BF23: Food | BG23: Restaurant | BI23: 2400 | BM23: 45921 | BN23: Transport | BO23: Fuel | BQ23: 2000 | BU23: 45951 | BV23: Food | BW23: Groceries | BY23: 2400 | CC23: 45982 | CD23: Food | CE23: Groceries | CG23: 2600 | CK23: 46012 | CL23: Education | CM23: Online Sub. | CO23: 500
A24: 2025-01-23 | B24: Transport | C24: Books | E24: 394 | I24: 2025-02-22 | J24: Food | K24: Movie | M24: 1321 | Q24: 45738 | R24: Transport | S24: Taxi | U24: 300 | Y24: 45769 | Z24: Entertainment | AA24: Video Game | AC24: 2000 | AG24: 45799 | AH24: Entertainment | AI24: Tickets | AK24: 1500 | AO24: 45830 | AP24: Health | AQ24: Doctor Visit | AS24: 1000 | AW24: 45860 | AX24: Entertainment | AY24: Tickets | BA24: 2000 | BE24: 45891 | BF24: Entertainment | BG24: Tickets | BI24: 1500 | BM24: 45922 | BN24: Entertainment | BO24: Tickets | BP24: 2500 | BQ24: 100 | BU24: 45952 | BV24: Entertainment | BW24: Social Event | BY24: 1000 | CC24: 45983 | CD24: Education | CE24: Online Tool | CG24: 600 | CK24: 46013 | CL24: Entertainment | CM24: Social Event | CO24: 3000
A25: 2025-01-24 | B25: Transport | C25: Clothes | E25: 1352 | I25: 2025-02-23 | J25: Health | K25: February Salary | L25: 2000 | M25: 1028 | Q25: 45739 | R25: Entertainment | S25: Gaming | U25: 1100 | Y25: 45770 | Z25: Food | AA25: Café shop | AB25: 12500 | AG25: 45800 | AH25: Food | AI25: Groceries | AK25: 2600 | AO25: 45831 | AP25: Entertainment | AQ25: Social Event | AS25: 1500 | AW25: 45861 | AX25: Health | AY25: Dental Visit | BA25: 3000 | BE25: 45892 | BF25: Education | BG25: Online Tool | BI25: 1000 | BM25: 45923 | BN25: Education | BO25: Workshop Fee | BQ25: 3000 | BU25: 45953 | BV25: Health | BW25: Checkup | BY25: 1000 | CC25: 45984 | CD25: Health | CE25: Pharmacy | CG25: 500 | CK25: 46014 | CL25: Health | CM25: Pharmacy | CO25: 700
A26: 2025-01-25 | B26: Shopping | C26: January Salary | D26: 1900 | E26: 1997 | I26: 2025-02-24 | J26: Education | K26: Books | M26: 189 | Q26: 45740 | R26: Food | S26: Groceries | U26: 2800 | Y26: 45771 | Z26: Health | AA26: Checkup | AC26: 1500 | AG26: 45801 | AH26: Health | AI26: Massage | AK26: 2500 | AO26: 45832 | AP26: Food | AQ26: Takeout | AS26: 700 | AW26: 45862 | AX26: Education | AY26: Stationery | BA26: 400 | BE26: 45893 | BF26: Food | BG26: Groceries | BI26: 2600 | BM26: 45924 | BN26: Food | BO26: Groceries | BP26: 15090 | BQ26: 100 | BU26: 45954 | BV26: Food | BW26: Delivery | BY26: 950 | CC26: 45985 | CD26: Entertainment | CE26: Tickets | CG26: 1500 | CK26: 46015 | CL26: Shopping | CM26: Last-minute Gifts | CN26: 4000
A27: 2025-01-26 | B27: Entertainment | C27: Doctor Visit | E27: 483 | I27: 2025-02-25 | J27: Entertainment | K27: Groceries | M27: 2335 | Q27: 45741 | R27: Health | S27: Gym Fee | U27: 1800 | Y27: 45772 | Z27: Shopping | AA27: Kitchenware | AC27: 1700 | AG27: 45802 | AH27: Education | AI27: Book | AK27: 700 | AO27: 45833 | AP27: Shopping | AQ27: Gift | AS27: 1000 | AW27: 45863 | AX27: Shopping | AY27: Gift | BA27: 2000 | BE27: 45894 | BF27: Health | BG27: Checkup | BI27: 1200 | BM27: 45925 | BN27: Health | BO27: Pharmacy | BQ27: 600 | BU27: 45955 | BV27: Education | BW27: Online Sub. | BY27: 500 | CC27: 45986 | CD27: Food | CE27: Delivery | CG27: 1000 | CK27: 46016 | CL27: Food | CM27: Holiday Dinner | CO27: 5000
A28: 2025-01-27 | B28: Salary | C28: Clothes | E28: 795 | I28: 2025-02-26 | J28: Salary | K28: Books | L28: 841 | M28: 41 | Q28: 45742 | R28: Shopping | S28: Shoes | U28: 4100 | Y28: 45773 | Z28: Education | AA28: Workshop Fee | AC28: 3000 | AG28: 45803 | AH28: Shopping | AI28: Gift | AK28: 1900 | AO28: 45834 | AP28: Transport | AQ28: Metro | AS28: 200 | AW28: 45864 | AX28: Food | AY28: Restaurant | AZ28: 80050 | BA28: 2500 | BE28: 45895 | BF28: Shopping | BG28: Home Decor | BI28: 1900 | BM28: 45926 | BN28: Shopping | BO28: Clothes | BQ28: 3600 | BU28: 45956 | BV28: Shopping | BW28: Clothes | BY28: 2500 | CC28: 45987 | CD28: Shopping | CE28: Home Decor | CG28: 2500 | CK28: 46017 | CL28: Transport | CM28: Train Ticket | CO28: 1500
A29: 2025-01-28 | B29: Health | C29: Groceries | D29: 50 | E29: 600 | I29: 2025-02-27 | J29: Food | K29: Groceries | M29: 1363 | Q29: 45743 | R29: Education | S29: Stationery | U29: 400 | Y29: 45774 | Z29: Food | AA29: Restaurant | AC29: 2100 | AG29: 45804 | AH29: Food | AI29: Restaurant | AK29: 2000 | AO29: 45835 | AP29: Utilities | AQ29: Internet Bill | AS29: 1000 | AW29: 45865 | AX29: Transport | AY29: Bus Fare | BA29: 150 | BE29: 45896 | BF29: Transport | BG29: Cab | BI29: 400 | BM29: 45927 | BN29: Transport | BO29: Metro | BQ29: 600 | BU29: 45957 | BV29: Transport | BW29: Metro | BY29: 250 | CC29: 45988 | CD29: Transport | CE29: Metro | CG29: 300 | CK29: 46018 | CL29: Utilities | CM29: Internet Bill | CO29: 1000
A30: 2025-01-29 | B30: Education | C30: January Salary | D30: 1000 | E30: 2333 | I30: 2025-02-28 | J30: Food | K30: Bus Fare | M30: 2066 | Q30: 45744 | R30: Utilities | S30: Internet Bill | U30: 1000 | Y30: 45775 | Z30: Transport | AA30: Train Ticket | AC30: 900 | AG30: 45805 | AH30: Transport | AI30: Metro | AK30: 300 | AO30: 45836 | AP30: Food | AQ30: Groceries | AS30: 1700 | AW30: 45866 | AX30: Utilities | AY30: Internet Bill | BA30: 1000 | BE30: 45897 | BF30: Utilities | BG30: Internet Bill | BI30: 1000 | BM30: 45928 | BN30: Utilities | BO30: Internet Bill | BQ30: 1000 | BU30: 45958 | BV30: Utilities | BW30: Internet Bill | BY30: 1000 | CC30: 45989 | CD30: Utilities | CE30: Internet Bill | CG30: 1000 | CK30: 46019 | CL30: Entertainment | CM30: New Year Tickets | CO30: 6000
A31: 2025-01-30 | B31: Salary | C31: Movie | E31: 1269 | Q31: 45745 | R31: Entertainment | S31: Social Event | U31: 2000 | Y31: 45776 | Z31: Utilities | AA31: Phone Bill | AB31: 600 | AG31: 45806 | AH31: Utilities | AI31: Internet Bill | AK31: 1000 | AO31: 45837 | AP31: Education | AQ31: Online Class | AS31: 1200 | AW31: 45867 | AX31: Entertainment | AY31: Streaming Sub. | BA31: 500 | BE31: 45898 | BF31: Entertainment | BG31: Gaming | BI31: 1500 | BM31: 45929 | BN31: Food | BO31: Restaurant | BP31: 1890 | BU31: 45959 | BV31: Entertainment | BW31: Tickets | BY31: 1500 | CC31: 45990 | CD31: Food | CE31: Restaurant | CG31: 2200 | CK31: 46020 | CL31: Food | CM31: Groceries | CO31: 2900
A32: 2025-01-31 | B32: Salary | C32: Groceries | E32: 12000 | Q32: 45746 | R32: Food | S32: Takeout | U32: 1150 | Y32: 45777 | Z32: Salary | AA32: Side Gig Income | AB32: 5000 | AG32: 45807 | AH32: Food | AI32: Delivery | AK32: 1100 | AO32: 45838 | AP32: Salary | AQ32: Consulting Fee | AR32: 6000 | AW32: 45868 | AX32: Food | AY32: Delivery | BA32: 950 | BE32: 45899 | BF32: Food | BG32: Delivery | BI32: 1100 | BM32: 45930 | BN32: Entertainment | BO32: Subscription | BQ32: 500 | BU32: 45960 | BV32: Food | BW32: Restaurant | BY32: 2000 | CC32: 45991 | CD32: Salary | CE32: Side Income | CF32: 5500 | CK32: 46021 | CL32: Shopping | CM32: Accessories | CO32: 1800
Q33: 45747 | R33: Health | S33: Physiotherapy | U33: 3000 | AG33: 45808 | AH33: Shopping | AI33: Subscription | AK33: 400 | AW33: 45869 | AX33: Salary | AY33: Project Pay | AZ33: 4500 | BE33: 45900 | BF33: Shopping | BG33: Subscription | BI33: 500 | BU33: 45961 | BV33: Salary | BW33: Small Income | BX33: 3000 | CK33: 46022 | CL33: Salary | CM33: Year-End Bonus | CN33: 8000
A35: Short Summary | C35: Income | D35: =SUM(D3:D32) -> 46640 | I35: Short Summary | K35: Income | L35: =SUM(L3:L30) -> 41101 | Q35: Short Summary | S35: Income | T35: =SUM(T3:T33) -> 34500 | Y35: Short Summary | AA35: Income | AB35: =SUM(AB3:AB32) -> 50670 | AG35: Short Summary | AI35: Income | AJ35: =SUM(AJ3:AJ33) -> 53020 | AO35: Short Summary | AQ35: Income | AR35: =SUM(AR3:AR32) -> 36000 | AW35: Short Summary | AY35: Income | AZ35: =SUM(AZ3:AZ33) -> 123550 | BE35: Short Summary | BG35: Income | BH35: =SUM(BH3:BH33) -> 30500 | BM35: Short Summary | BO35: Income | BP35: =SUM(BP3:BP32) -> 67980 | BU35: Short Summary | BW35: Income | BX35: =SUM(BX3:BX33) -> 57530 | CC35: Short Summary | CE35: Income | CF35: =SUM(CF3:CF32) -> 42000 | CK35: Short Summary | CM35: Income | CN35: =SUM(CN3:CN33) -> 73200
C36: Expense | E36: =SUM(E3:E32) -> 44937 | K36: Expense | M36: =SUM(M3:M30) -> 39428 | S36: Expense | U36: =SUM(U3:U33) -> 71300 | AA36: Expense | AC36: =SUM(AC3:AC32) -> 48500 | AI36: Expense | AK36: =SUM(AK3:AK33) -> 52100 | AQ36: Expense | AS36: =SUM(AS3:AS32) -> 39400 | AY36: Expense | BA36: =SUM(BA3:BA33) -> 54100 | BG36: Expense | BI36: =SUM(BI3:BI33) -> 72200 | BO36: Expense | BQ36: =SUM(BQ3:BQ32) -> 67980 | BW36: Expense | BY36: =SUM(BY3:BY33) -> 40190 | CE36: Expense | CG36: =SUM(CG3:CG32) -> 55250 | CM36: Expense | CO36: =SUM(CO3:CO33) -> 67450
C37: Max Income | D37: =MAX(D3:D32) -> 40000 | K37: Max Income | L37: =MAX(L3:L30) -> 30000 | S37: Max Income | T37: =MAX(T3:T33) -> 31500 | AA37: Max Income | AB37: =MAX(AB3:AB32) -> 30500 | AI37: Max Income | AJ37: =SUM(AJ3:AJ33) -> 53020 | AQ37: Max Income | AR37: =MAX(AR3:AR32) -> 30000 | AY37: Max Income | AZ37: =MAX(AZ3:AZ33) -> 80050 | BG37: Max Income | BH37: =MAX(BH3:BH33) -> 30500 | BO37: Max Income | BP37: =MAX(BP3:BP32) -> 31000 | BW37: Max Income | BX37: =MAX(BX3:BX33) -> 28000 | CE37: Max Income | CF37: =MAX(CF3:CF32) -> 31500 | CM37: Max Income | CN37: =MAX(CN3:CN33) -> 32000
C38: Max Expense | E38: =MAX(E3:E32) -> 12000 | K38: Max Expense | M38: =MAX(M3:M30) -> 2335 | S38: Max Expense | U38: =MAX(U3:U33) -> 15000 | AA38: Max Expense | AC38: =MAX(AC3:AC32) -> 15000 | AI38: Max Expense | AK38: =SUM(AK3:AK33) -> 52100 | AQ38: Max Expense | AS38: =MAX(AS3:AS32) -> 15000 | AY38: Max Expense | BA38: =MAX(BA3:BA33) -> 15000 | BG38: Max Expense | BI38: =MAX(BI3:BI33) -> 15000 | BO38: Max Expense | BQ38: =MAX(BQ3:BQ32) -> 15000 | BW38: Max Expense | BY38: =MAX(BY3:BY33) -> 5000 | CE38: Max Expense | CG38: =MAX(CG3:CG32) -> 15000 | CM38: Max Expense | CO38: =MAX(CO3:CO33) -> 8000
C39: Min Income | D39: =MIN(D3:D32) -> 50 | K39: Min Income | L39: =MIN(L3:L30) -> 50 | S39: Min Income | T39: =MIN(T3:T33) -> 3000 | AA39: Min Income | AB39: =MIN(AB3:AB32) -> 600 | AI39: Min Income | AJ39: =MIN(AJ3:AJ33) -> 7020 | AQ39: Min Income | AR39: =MIN(AR3:AR32) -> 6000 | AY39: Min Income | AZ39: =MIN(AZ3:AZ33) -> 3000 | BG39: Min Income | BH39: =MIN(BH3:BH33) -> 30500 | BO39: Min Income | BP39: =MIN(BP3:BP32) -> 900 | BW39: Min Income | BX39: =MIN(BX3:BX33) -> 3000 | CE39: Min Income | CF39: =MIN(CF3:CF32) -> 5000 | CM39: Min Income | CN39: =MIN(CN3:CN33) -> 1200
C40: Min Expense | E40: =MIN(E3:E32) -> 114 | K40: Min Expense | M40: =MIN(M3:M30) -> 41 | S40: Min Expense | U40: =MIN(U3:U33) -> 150 | AA40: Min Expense | AC40: =MIN(AC3:AC32) -> 100 | AI40: Min Expense | AK40: =MIN(AK3:AK33) -> 100 | AQ40: Min Expense | AS40: =MIN(AS3:AS32) -> 100 | AY40: Min Expense | BA40: =MIN(BA3:BA33) -> 150 | BG40: Min Expense | BI40: =MIN(BI3:BI33) -> 400 | BO40: Min Expense | BQ40: =MIN(BQ3:BQ32) -> 100 | BW40: Min Expense | BY40: =MIN(BY3:BY33) -> 150 | CE40: Min Expense | CG40: =MIN(CG3:CG32) -> 100 | CM40: Min Expense | CO40: =MIN(CO3:CO33) -> 500
C41: Saving | D41: =SUM(D35-E36) -> 1703 | K41: Saving | L41: =L35-M36 -> 1673 | S41: Saving | T41: =T35-U36 -> -36800 | AA41: Saving | AB41: =AB35-AC36 -> 2170 | AI41: Saving | AJ41: =AJ35-AK36 -> 920 | AQ41: Saving | AR41: =AR35-AS36 -> -3400 | AY41: Saving | AZ41: =AZ35-BA36 -> 69450 | BG41: Saving | BH41: =BH35-BI36 -> -41700 | BO41: Saving | BP41: =BP35-BQ36 -> 0 | BW41: Saving | BX41: =BX35-BY36 -> 17340 | CE41: Saving | CF41: =CF35-CG36 -> -13250 | CM41: Saving | CN41: =CN35-CO36 -> 5750
...
